[2024-10-07T06:28:12.983+0000] {taskinstance.py:1087} INFO - Dependencies all met for <TaskInstance: pinecone_embedding_test_dag.embed_convertapi_pages manual__2024-10-07T06:28:00.984847+00:00 [queued]>
[2024-10-07T06:28:13.098+0000] {taskinstance.py:1087} INFO - Dependencies all met for <TaskInstance: pinecone_embedding_test_dag.embed_convertapi_pages manual__2024-10-07T06:28:00.984847+00:00 [queued]>
[2024-10-07T06:28:13.098+0000] {taskinstance.py:1283} INFO - 
--------------------------------------------------------------------------------
[2024-10-07T06:28:13.099+0000] {taskinstance.py:1284} INFO - Starting attempt 1 of 3
[2024-10-07T06:28:13.099+0000] {taskinstance.py:1285} INFO - 
--------------------------------------------------------------------------------
[2024-10-07T06:28:13.114+0000] {taskinstance.py:1304} INFO - Executing <Task(PythonOperator): embed_convertapi_pages> on 2024-10-07 06:28:00.984847+00:00
[2024-10-07T06:28:13.118+0000] {standard_task_runner.py:55} INFO - Started process 1197 to run task
[2024-10-07T06:28:13.120+0000] {standard_task_runner.py:82} INFO - Running: ['***', 'tasks', 'run', 'pinecone_embedding_test_dag', 'embed_convertapi_pages', 'manual__2024-10-07T06:28:00.984847+00:00', '--job-id', '413', '--raw', '--subdir', 'DAGS_FOLDER/Pinecone_Test.py', '--cfg-path', '/tmp/tmpwamjo0z_']
[2024-10-07T06:28:13.121+0000] {standard_task_runner.py:83} INFO - Job 413: Subtask embed_convertapi_pages
[2024-10-07T06:28:13.145+0000] {logging_mixin.py:137} WARNING - /home/***/.local/lib/python3.7/site-packages/***/settings.py:249 DeprecationWarning: The sql_alchemy_conn option in [core] has been moved to the sql_alchemy_conn option in [database] - the old setting has been used, but please update your config.
[2024-10-07T06:28:13.238+0000] {task_command.py:389} INFO - Running <TaskInstance: pinecone_embedding_test_dag.embed_convertapi_pages manual__2024-10-07T06:28:00.984847+00:00 [running]> on host 2478cb613add
[2024-10-07T06:28:13.350+0000] {taskinstance.py:1513} INFO - Exporting the following env vars:
AIRFLOW_CTX_DAG_OWNER=***
AIRFLOW_CTX_DAG_ID=pinecone_embedding_test_dag
AIRFLOW_CTX_TASK_ID=embed_convertapi_pages
AIRFLOW_CTX_EXECUTION_DATE=2024-10-07T06:28:00.984847+00:00
AIRFLOW_CTX_TRY_NUMBER=1
AIRFLOW_CTX_DAG_RUN_ID=manual__2024-10-07T06:28:00.984847+00:00
[2024-10-07T06:28:13.378+0000] {connectionpool.py:813} WARNING - Retrying (Retry(total=2, connect=None, read=None, redirect=None, status=None)) after connection broken by 'NewConnectionError('<urllib3.connection.HTTPSConnection object at 0x7faefbad0050>: Failed to establish a new connection: [Errno -2] Name or service not known')': /databases
[2024-10-07T06:28:13.381+0000] {connectionpool.py:813} WARNING - Retrying (Retry(total=1, connect=None, read=None, redirect=None, status=None)) after connection broken by 'NewConnectionError('<urllib3.connection.HTTPSConnection object at 0x7faefbad0210>: Failed to establish a new connection: [Errno -2] Name or service not known')': /databases
[2024-10-07T06:28:13.383+0000] {connectionpool.py:813} WARNING - Retrying (Retry(total=0, connect=None, read=None, redirect=None, status=None)) after connection broken by 'NewConnectionError('<urllib3.connection.HTTPSConnection object at 0x7faefbad0410>: Failed to establish a new connection: [Errno -2] Name or service not known')': /databases
[2024-10-07T06:28:13.386+0000] {logging_mixin.py:137} INFO - Error creating Pinecone index: HTTPSConnectionPool(host='controller.us-east1-aws.pinecone.io', port=443): Max retries exceeded with url: /databases (Caused by NewConnectionError('<urllib3.connection.HTTPSConnection object at 0x7faefbad0610>: Failed to establish a new connection: [Errno -2] Name or service not known'))
[2024-10-07T06:28:13.784+0000] {connectionpool.py:813} WARNING - Retrying (Retry(total=2, connect=None, read=None, redirect=None, status=None)) after connection broken by 'NewConnectionError('<urllib3.connection.HTTPSConnection object at 0x7faefb9b06d0>: Failed to establish a new connection: [Errno -2] Name or service not known')': /vectors/upsert
[2024-10-07T06:28:13.786+0000] {connectionpool.py:813} WARNING - Retrying (Retry(total=1, connect=None, read=None, redirect=None, status=None)) after connection broken by 'NewConnectionError('<urllib3.connection.HTTPSConnection object at 0x7faefba41a90>: Failed to establish a new connection: [Errno -2] Name or service not known')': /vectors/upsert
[2024-10-07T06:28:13.789+0000] {connectionpool.py:813} WARNING - Retrying (Retry(total=0, connect=None, read=None, redirect=None, status=None)) after connection broken by 'NewConnectionError('<urllib3.connection.HTTPSConnection object at 0x7faefba95a50>: Failed to establish a new connection: [Errno -2] Name or service not known')': /vectors/upsert
[2024-10-07T06:28:13.792+0000] {logging_mixin.py:137} INFO - Failed to process /tmp/pymupdf_021a5339-744f-42b7-bd9b-9368b3efda7a.pdf.json: HTTPSConnectionPool(host='convertapi-index-unknown.svc.us-east1-aws.pinecone.io', port=443): Max retries exceeded with url: /vectors/upsert (Caused by NewConnectionError('<urllib3.connection.HTTPSConnection object at 0x7faefba2ed90>: Failed to establish a new connection: [Errno -2] Name or service not known'))
[2024-10-07T06:28:13.955+0000] {connectionpool.py:813} WARNING - Retrying (Retry(total=2, connect=None, read=None, redirect=None, status=None)) after connection broken by 'NewConnectionError('<urllib3.connection.HTTPSConnection object at 0x7faefbae0310>: Failed to establish a new connection: [Errno -2] Name or service not known')': /vectors/upsert
[2024-10-07T06:28:13.958+0000] {connectionpool.py:813} WARNING - Retrying (Retry(total=1, connect=None, read=None, redirect=None, status=None)) after connection broken by 'NewConnectionError('<urllib3.connection.HTTPSConnection object at 0x7faefba4c890>: Failed to establish a new connection: [Errno -2] Name or service not known')': /vectors/upsert
[2024-10-07T06:28:13.961+0000] {connectionpool.py:813} WARNING - Retrying (Retry(total=0, connect=None, read=None, redirect=None, status=None)) after connection broken by 'NewConnectionError('<urllib3.connection.HTTPSConnection object at 0x7faefb9b0a50>: Failed to establish a new connection: [Errno -2] Name or service not known')': /vectors/upsert
[2024-10-07T06:28:13.965+0000] {logging_mixin.py:137} INFO - Failed to process /tmp/pymupdf_366e2f2b-8632-4ef2-81eb-bc3877489217.pdf.json: HTTPSConnectionPool(host='convertapi-index-unknown.svc.us-east1-aws.pinecone.io', port=443): Max retries exceeded with url: /vectors/upsert (Caused by NewConnectionError('<urllib3.connection.HTTPSConnection object at 0x7faefba95150>: Failed to establish a new connection: [Errno -2] Name or service not known'))
[2024-10-07T06:28:14.219+0000] {connectionpool.py:813} WARNING - Retrying (Retry(total=2, connect=None, read=None, redirect=None, status=None)) after connection broken by 'NewConnectionError('<urllib3.connection.HTTPSConnection object at 0x7faefba088d0>: Failed to establish a new connection: [Errno -2] Name or service not known')': /vectors/upsert
[2024-10-07T06:28:14.222+0000] {connectionpool.py:813} WARNING - Retrying (Retry(total=1, connect=None, read=None, redirect=None, status=None)) after connection broken by 'NewConnectionError('<urllib3.connection.HTTPSConnection object at 0x7faefba08e50>: Failed to establish a new connection: [Errno -2] Name or service not known')': /vectors/upsert
[2024-10-07T06:28:14.224+0000] {connectionpool.py:813} WARNING - Retrying (Retry(total=0, connect=None, read=None, redirect=None, status=None)) after connection broken by 'NewConnectionError('<urllib3.connection.HTTPSConnection object at 0x7faefba2e090>: Failed to establish a new connection: [Errno -2] Name or service not known')': /vectors/upsert
[2024-10-07T06:28:14.227+0000] {logging_mixin.py:137} INFO - Failed to process /tmp/pymupdf_634fca59-03b2-4cdf-9ce4-0205df22f256.pdf.json: HTTPSConnectionPool(host='convertapi-index-unknown.svc.us-east1-aws.pinecone.io', port=443): Max retries exceeded with url: /vectors/upsert (Caused by NewConnectionError('<urllib3.connection.HTTPSConnection object at 0x7faefba51690>: Failed to establish a new connection: [Errno -2] Name or service not known'))
[2024-10-07T06:28:14.450+0000] {connectionpool.py:813} WARNING - Retrying (Retry(total=2, connect=None, read=None, redirect=None, status=None)) after connection broken by 'NewConnectionError('<urllib3.connection.HTTPSConnection object at 0x7faefbad0310>: Failed to establish a new connection: [Errno -2] Name or service not known')': /vectors/upsert
[2024-10-07T06:28:14.453+0000] {connectionpool.py:813} WARNING - Retrying (Retry(total=1, connect=None, read=None, redirect=None, status=None)) after connection broken by 'NewConnectionError('<urllib3.connection.HTTPSConnection object at 0x7faefba415d0>: Failed to establish a new connection: [Errno -2] Name or service not known')': /vectors/upsert
[2024-10-07T06:28:14.455+0000] {connectionpool.py:813} WARNING - Retrying (Retry(total=0, connect=None, read=None, redirect=None, status=None)) after connection broken by 'NewConnectionError('<urllib3.connection.HTTPSConnection object at 0x7faefba25cd0>: Failed to establish a new connection: [Errno -2] Name or service not known')': /vectors/upsert
[2024-10-07T06:28:14.458+0000] {logging_mixin.py:137} INFO - Failed to process /tmp/pymupdf_8f697523-6988-4c4f-8d72-760a45681f68.pdf.json: HTTPSConnectionPool(host='convertapi-index-unknown.svc.us-east1-aws.pinecone.io', port=443): Max retries exceeded with url: /vectors/upsert (Caused by NewConnectionError('<urllib3.connection.HTTPSConnection object at 0x7faefba89250>: Failed to establish a new connection: [Errno -2] Name or service not known'))
[2024-10-07T06:28:15.110+0000] {connectionpool.py:813} WARNING - Retrying (Retry(total=2, connect=None, read=None, redirect=None, status=None)) after connection broken by 'NewConnectionError('<urllib3.connection.HTTPSConnection object at 0x7faefba894d0>: Failed to establish a new connection: [Errno -2] Name or service not known')': /vectors/upsert
[2024-10-07T06:28:15.113+0000] {connectionpool.py:813} WARNING - Retrying (Retry(total=1, connect=None, read=None, redirect=None, status=None)) after connection broken by 'NewConnectionError('<urllib3.connection.HTTPSConnection object at 0x7faefba6e3d0>: Failed to establish a new connection: [Errno -2] Name or service not known')': /vectors/upsert
[2024-10-07T06:28:15.116+0000] {connectionpool.py:813} WARNING - Retrying (Retry(total=0, connect=None, read=None, redirect=None, status=None)) after connection broken by 'NewConnectionError('<urllib3.connection.HTTPSConnection object at 0x7faefba6e250>: Failed to establish a new connection: [Errno -2] Name or service not known')': /vectors/upsert
[2024-10-07T06:28:15.118+0000] {logging_mixin.py:137} INFO - Failed to process /tmp/pymupdf_example.pdf.json: HTTPSConnectionPool(host='convertapi-index-unknown.svc.us-east1-aws.pinecone.io', port=443): Max retries exceeded with url: /vectors/upsert (Caused by NewConnectionError('<urllib3.connection.HTTPSConnection object at 0x7faefba6e510>: Failed to establish a new connection: [Errno -2] Name or service not known'))
[2024-10-07T06:28:15.119+0000] {python.py:177} INFO - Done. Returned value was: None
[2024-10-07T06:28:15.142+0000] {taskinstance.py:1327} INFO - Marking task as SUCCESS. dag_id=pinecone_embedding_test_dag, task_id=embed_convertapi_pages, execution_date=20241007T062800, start_date=20241007T062812, end_date=20241007T062815
[2024-10-07T06:28:15.179+0000] {local_task_job.py:159} INFO - Task exited with return code 0
[2024-10-07T06:28:15.208+0000] {taskinstance.py:2582} INFO - 0 downstream tasks scheduled from follow-on schedule check
