[2024-10-04T15:42:41.411+0000] {taskinstance.py:1087} INFO - Dependencies all met for <TaskInstance: pdf_extraction_stages.list_pdfs_in_s3 manual__2024-10-04T15:42:40.705944+00:00 [queued]>
[2024-10-04T15:42:41.421+0000] {taskinstance.py:1087} INFO - Dependencies all met for <TaskInstance: pdf_extraction_stages.list_pdfs_in_s3 manual__2024-10-04T15:42:40.705944+00:00 [queued]>
[2024-10-04T15:42:41.421+0000] {taskinstance.py:1283} INFO - 
--------------------------------------------------------------------------------
[2024-10-04T15:42:41.422+0000] {taskinstance.py:1284} INFO - Starting attempt 1 of 2
[2024-10-04T15:42:41.423+0000] {taskinstance.py:1285} INFO - 
--------------------------------------------------------------------------------
[2024-10-04T15:42:41.437+0000] {taskinstance.py:1304} INFO - Executing <Task(PythonOperator): list_pdfs_in_s3> on 2024-10-04 15:42:40.705944+00:00
[2024-10-04T15:42:41.440+0000] {standard_task_runner.py:55} INFO - Started process 371 to run task
[2024-10-04T15:42:41.443+0000] {standard_task_runner.py:82} INFO - Running: ['***', 'tasks', 'run', 'pdf_extraction_stages', 'list_pdfs_in_s3', 'manual__2024-10-04T15:42:40.705944+00:00', '--job-id', '5', '--raw', '--subdir', 'DAGS_FOLDER/PDF-ETL.py', '--cfg-path', '/tmp/tmp4su4x5kl']
[2024-10-04T15:42:41.443+0000] {standard_task_runner.py:83} INFO - Job 5: Subtask list_pdfs_in_s3
[2024-10-04T15:42:41.466+0000] {logging_mixin.py:137} WARNING - /home/***/.local/lib/python3.7/site-packages/***/settings.py:249 DeprecationWarning: The sql_alchemy_conn option in [core] has been moved to the sql_alchemy_conn option in [database] - the old setting has been used, but please update your config.
[2024-10-04T15:42:41.538+0000] {task_command.py:389} INFO - Running <TaskInstance: pdf_extraction_stages.list_pdfs_in_s3 manual__2024-10-04T15:42:40.705944+00:00 [running]> on host b1045350cd33
[2024-10-04T15:42:41.727+0000] {taskinstance.py:1513} INFO - Exporting the following env vars:
AIRFLOW_CTX_DAG_OWNER=***
AIRFLOW_CTX_DAG_ID=pdf_extraction_stages
AIRFLOW_CTX_TASK_ID=list_pdfs_in_s3
AIRFLOW_CTX_EXECUTION_DATE=2024-10-04T15:42:40.705944+00:00
AIRFLOW_CTX_TRY_NUMBER=1
AIRFLOW_CTX_DAG_RUN_ID=manual__2024-10-04T15:42:40.705944+00:00
[2024-10-04T15:42:41.730+0000] {taskinstance.py:1772} ERROR - Task failed with exception
Traceback (most recent call last):
  File "/home/airflow/.local/lib/python3.7/site-packages/airflow/operators/python.py", line 175, in execute
    return_value = self.execute_callable()
  File "/home/airflow/.local/lib/python3.7/site-packages/airflow/operators/python.py", line 192, in execute_callable
    return self.python_callable(*self.op_args, **self.op_kwargs)
  File "/opt/airflow/dags/PDF-ETL.py", line 27, in list_pdfs_in_s3
    response = s3.list_objects_v2(Bucket=bucket_name)
  File "/home/airflow/.local/lib/python3.7/site-packages/botocore/client.py", line 530, in _api_call
    return self._make_api_call(operation_name, kwargs)
  File "/home/airflow/.local/lib/python3.7/site-packages/botocore/client.py", line 944, in _make_api_call
    operation_model, request_dict, request_context
  File "/home/airflow/.local/lib/python3.7/site-packages/botocore/client.py", line 966, in _make_request
    return self._endpoint.make_request(operation_model, request_dict)
  File "/home/airflow/.local/lib/python3.7/site-packages/botocore/endpoint.py", line 119, in make_request
    return self._send_request(request_dict, operation_model)
  File "/home/airflow/.local/lib/python3.7/site-packages/botocore/endpoint.py", line 198, in _send_request
    request = self.create_request(request_dict, operation_model)
  File "/home/airflow/.local/lib/python3.7/site-packages/botocore/endpoint.py", line 137, in create_request
    operation_name=operation_model.name,
  File "/home/airflow/.local/lib/python3.7/site-packages/botocore/hooks.py", line 412, in emit
    return self._emitter.emit(aliased_event_name, **kwargs)
  File "/home/airflow/.local/lib/python3.7/site-packages/botocore/hooks.py", line 256, in emit
    return self._emit(event_name, kwargs)
  File "/home/airflow/.local/lib/python3.7/site-packages/botocore/hooks.py", line 239, in _emit
    response = handler(**kwargs)
  File "/home/airflow/.local/lib/python3.7/site-packages/botocore/signers.py", line 105, in handler
    return self.sign(operation_name, request)
  File "/home/airflow/.local/lib/python3.7/site-packages/botocore/signers.py", line 189, in sign
    auth.add_auth(request)
  File "/home/airflow/.local/lib/python3.7/site-packages/botocore/auth.py", line 418, in add_auth
    raise NoCredentialsError()
botocore.exceptions.NoCredentialsError: Unable to locate credentials
[2024-10-04T15:42:41.750+0000] {taskinstance.py:1327} INFO - Marking task as UP_FOR_RETRY. dag_id=pdf_extraction_stages, task_id=list_pdfs_in_s3, execution_date=20241004T154240, start_date=20241004T154241, end_date=20241004T154241
[2024-10-04T15:42:41.763+0000] {standard_task_runner.py:105} ERROR - Failed to execute job 5 for task list_pdfs_in_s3 (Unable to locate credentials; 371)
[2024-10-04T15:42:41.775+0000] {local_task_job.py:159} INFO - Task exited with return code 1
[2024-10-04T15:42:41.805+0000] {taskinstance.py:2582} INFO - 0 downstream tasks scheduled from follow-on schedule check
