[2024-10-07T06:15:13.418+0000] {taskinstance.py:1087} INFO - Dependencies all met for <TaskInstance: pinecone_embedding_test_dag.embed_pymupdf_pages manual__2024-10-07T06:15:00.334978+00:00 [queued]>
[2024-10-07T06:15:13.647+0000] {taskinstance.py:1087} INFO - Dependencies all met for <TaskInstance: pinecone_embedding_test_dag.embed_pymupdf_pages manual__2024-10-07T06:15:00.334978+00:00 [queued]>
[2024-10-07T06:15:13.648+0000] {taskinstance.py:1283} INFO - 
--------------------------------------------------------------------------------
[2024-10-07T06:15:13.649+0000] {taskinstance.py:1284} INFO - Starting attempt 1 of 3
[2024-10-07T06:15:13.649+0000] {taskinstance.py:1285} INFO - 
--------------------------------------------------------------------------------
[2024-10-07T06:15:13.681+0000] {taskinstance.py:1304} INFO - Executing <Task(PythonOperator): embed_pymupdf_pages> on 2024-10-07 06:15:00.334978+00:00
[2024-10-07T06:15:13.690+0000] {standard_task_runner.py:55} INFO - Started process 352 to run task
[2024-10-07T06:15:13.693+0000] {standard_task_runner.py:82} INFO - Running: ['***', 'tasks', 'run', 'pinecone_embedding_test_dag', 'embed_pymupdf_pages', 'manual__2024-10-07T06:15:00.334978+00:00', '--job-id', '400', '--raw', '--subdir', 'DAGS_FOLDER/Pinecone_Test.py', '--cfg-path', '/tmp/tmpvx8apzvd']
[2024-10-07T06:15:13.694+0000] {standard_task_runner.py:83} INFO - Job 400: Subtask embed_pymupdf_pages
[2024-10-07T06:15:13.730+0000] {logging_mixin.py:137} WARNING - /home/***/.local/lib/python3.7/site-packages/***/settings.py:249 DeprecationWarning: The sql_alchemy_conn option in [core] has been moved to the sql_alchemy_conn option in [database] - the old setting has been used, but please update your config.
[2024-10-07T06:15:13.850+0000] {task_command.py:389} INFO - Running <TaskInstance: pinecone_embedding_test_dag.embed_pymupdf_pages manual__2024-10-07T06:15:00.334978+00:00 [running]> on host 2478cb613add
[2024-10-07T06:15:14.004+0000] {taskinstance.py:1513} INFO - Exporting the following env vars:
AIRFLOW_CTX_DAG_OWNER=***
AIRFLOW_CTX_DAG_ID=pinecone_embedding_test_dag
AIRFLOW_CTX_TASK_ID=embed_pymupdf_pages
AIRFLOW_CTX_EXECUTION_DATE=2024-10-07T06:15:00.334978+00:00
AIRFLOW_CTX_TRY_NUMBER=1
AIRFLOW_CTX_DAG_RUN_ID=manual__2024-10-07T06:15:00.334978+00:00
[2024-10-07T06:15:14.046+0000] {connectionpool.py:813} WARNING - Retrying (Retry(total=2, connect=None, read=None, redirect=None, status=None)) after connection broken by 'NewConnectionError('<urllib3.connection.HTTPSConnection object at 0x7faefbac13d0>: Failed to establish a new connection: [Errno -2] Name or service not known')': /databases
[2024-10-07T06:15:14.050+0000] {connectionpool.py:813} WARNING - Retrying (Retry(total=1, connect=None, read=None, redirect=None, status=None)) after connection broken by 'NewConnectionError('<urllib3.connection.HTTPSConnection object at 0x7faefbac1750>: Failed to establish a new connection: [Errno -2] Name or service not known')': /databases
[2024-10-07T06:15:14.055+0000] {connectionpool.py:813} WARNING - Retrying (Retry(total=0, connect=None, read=None, redirect=None, status=None)) after connection broken by 'NewConnectionError('<urllib3.connection.HTTPSConnection object at 0x7faefbac1950>: Failed to establish a new connection: [Errno -2] Name or service not known')': /databases
[2024-10-07T06:15:14.059+0000] {logging_mixin.py:137} INFO - Error creating Pinecone index: HTTPSConnectionPool(host='controller.us-east1-aws.pinecone.io', port=443): Max retries exceeded with url: /databases (Caused by NewConnectionError('<urllib3.connection.HTTPSConnection object at 0x7faefbac1b50>: Failed to establish a new connection: [Errno -2] Name or service not known'))
[2024-10-07T06:16:44.811+0000] {connectionpool.py:813} WARNING - Retrying (Retry(total=2, connect=None, read=None, redirect=None, status=None)) after connection broken by 'NewConnectionError('<urllib3.connection.HTTPSConnection object at 0x7faefba733d0>: Failed to establish a new connection: [Errno -2] Name or service not known')': /vectors/upsert
[2024-10-07T06:16:44.815+0000] {connectionpool.py:813} WARNING - Retrying (Retry(total=1, connect=None, read=None, redirect=None, status=None)) after connection broken by 'NewConnectionError('<urllib3.connection.HTTPSConnection object at 0x7faefba6bc50>: Failed to establish a new connection: [Errno -2] Name or service not known')': /vectors/upsert
[2024-10-07T06:16:44.819+0000] {connectionpool.py:813} WARNING - Retrying (Retry(total=0, connect=None, read=None, redirect=None, status=None)) after connection broken by 'NewConnectionError('<urllib3.connection.HTTPSConnection object at 0x7faefba9ad10>: Failed to establish a new connection: [Errno -2] Name or service not known')': /vectors/upsert
[2024-10-07T06:16:44.823+0000] {logging_mixin.py:137} INFO - Failed to process /tmp/pymupdf_021a5339-744f-42b7-bd9b-9368b3efda7a.pdf.json: HTTPSConnectionPool(host='pymupdf-index-unknown.svc.us-east1-aws.pinecone.io', port=443): Max retries exceeded with url: /vectors/upsert (Caused by NewConnectionError('<urllib3.connection.HTTPSConnection object at 0x7faefba93790>: Failed to establish a new connection: [Errno -2] Name or service not known'))
[2024-10-07T06:16:45.575+0000] {connectionpool.py:813} WARNING - Retrying (Retry(total=2, connect=None, read=None, redirect=None, status=None)) after connection broken by 'NewConnectionError('<urllib3.connection.HTTPSConnection object at 0x7faf009c05d0>: Failed to establish a new connection: [Errno -2] Name or service not known')': /vectors/upsert
[2024-10-07T06:16:45.578+0000] {connectionpool.py:813} WARNING - Retrying (Retry(total=1, connect=None, read=None, redirect=None, status=None)) after connection broken by 'NewConnectionError('<urllib3.connection.HTTPSConnection object at 0x7faefba2a590>: Failed to establish a new connection: [Errno -2] Name or service not known')': /vectors/upsert
[2024-10-07T06:16:45.581+0000] {connectionpool.py:813} WARNING - Retrying (Retry(total=0, connect=None, read=None, redirect=None, status=None)) after connection broken by 'NewConnectionError('<urllib3.connection.HTTPSConnection object at 0x7faefbab1410>: Failed to establish a new connection: [Errno -2] Name or service not known')': /vectors/upsert
[2024-10-07T06:16:45.585+0000] {logging_mixin.py:137} INFO - Failed to process /tmp/pymupdf_366e2f2b-8632-4ef2-81eb-bc3877489217.pdf.json: HTTPSConnectionPool(host='pymupdf-index-unknown.svc.us-east1-aws.pinecone.io', port=443): Max retries exceeded with url: /vectors/upsert (Caused by NewConnectionError('<urllib3.connection.HTTPSConnection object at 0x7faefba73350>: Failed to establish a new connection: [Errno -2] Name or service not known'))
[2024-10-07T06:16:45.972+0000] {connectionpool.py:813} WARNING - Retrying (Retry(total=2, connect=None, read=None, redirect=None, status=None)) after connection broken by 'NewConnectionError('<urllib3.connection.HTTPSConnection object at 0x7faefba39e50>: Failed to establish a new connection: [Errno -2] Name or service not known')': /vectors/upsert
[2024-10-07T06:16:45.975+0000] {connectionpool.py:813} WARNING - Retrying (Retry(total=1, connect=None, read=None, redirect=None, status=None)) after connection broken by 'NewConnectionError('<urllib3.connection.HTTPSConnection object at 0x7faefba39f10>: Failed to establish a new connection: [Errno -2] Name or service not known')': /vectors/upsert
[2024-10-07T06:16:45.979+0000] {connectionpool.py:813} WARNING - Retrying (Retry(total=0, connect=None, read=None, redirect=None, status=None)) after connection broken by 'NewConnectionError('<urllib3.connection.HTTPSConnection object at 0x7faefba7bfd0>: Failed to establish a new connection: [Errno -2] Name or service not known')': /vectors/upsert
[2024-10-07T06:16:45.982+0000] {logging_mixin.py:137} INFO - Failed to process /tmp/pymupdf_634fca59-03b2-4cdf-9ce4-0205df22f256.pdf.json: HTTPSConnectionPool(host='pymupdf-index-unknown.svc.us-east1-aws.pinecone.io', port=443): Max retries exceeded with url: /vectors/upsert (Caused by NewConnectionError('<urllib3.connection.HTTPSConnection object at 0x7faefbac1590>: Failed to establish a new connection: [Errno -2] Name or service not known'))
[2024-10-07T06:16:46.479+0000] {connectionpool.py:813} WARNING - Retrying (Retry(total=2, connect=None, read=None, redirect=None, status=None)) after connection broken by 'NewConnectionError('<urllib3.connection.HTTPSConnection object at 0x7faefb9f8250>: Failed to establish a new connection: [Errno -2] Name or service not known')': /vectors/upsert
[2024-10-07T06:16:46.482+0000] {connectionpool.py:813} WARNING - Retrying (Retry(total=1, connect=None, read=None, redirect=None, status=None)) after connection broken by 'NewConnectionError('<urllib3.connection.HTTPSConnection object at 0x7faefbac1d10>: Failed to establish a new connection: [Errno -2] Name or service not known')': /vectors/upsert
[2024-10-07T06:16:46.487+0000] {connectionpool.py:813} WARNING - Retrying (Retry(total=0, connect=None, read=None, redirect=None, status=None)) after connection broken by 'NewConnectionError('<urllib3.connection.HTTPSConnection object at 0x7faefba029d0>: Failed to establish a new connection: [Errno -2] Name or service not known')': /vectors/upsert
[2024-10-07T06:16:46.490+0000] {logging_mixin.py:137} INFO - Failed to process /tmp/pymupdf_8f697523-6988-4c4f-8d72-760a45681f68.pdf.json: HTTPSConnectionPool(host='pymupdf-index-unknown.svc.us-east1-aws.pinecone.io', port=443): Max retries exceeded with url: /vectors/upsert (Caused by NewConnectionError('<urllib3.connection.HTTPSConnection object at 0x7faefba02710>: Failed to establish a new connection: [Errno -2] Name or service not known'))
[2024-10-07T06:16:47.874+0000] {connectionpool.py:813} WARNING - Retrying (Retry(total=2, connect=None, read=None, redirect=None, status=None)) after connection broken by 'NewConnectionError('<urllib3.connection.HTTPSConnection object at 0x7faefb9f8210>: Failed to establish a new connection: [Errno -2] Name or service not known')': /vectors/upsert
[2024-10-07T06:16:47.877+0000] {connectionpool.py:813} WARNING - Retrying (Retry(total=1, connect=None, read=None, redirect=None, status=None)) after connection broken by 'NewConnectionError('<urllib3.connection.HTTPSConnection object at 0x7faefba6a290>: Failed to establish a new connection: [Errno -2] Name or service not known')': /vectors/upsert
[2024-10-07T06:16:47.881+0000] {connectionpool.py:813} WARNING - Retrying (Retry(total=0, connect=None, read=None, redirect=None, status=None)) after connection broken by 'NewConnectionError('<urllib3.connection.HTTPSConnection object at 0x7faefba6a3d0>: Failed to establish a new connection: [Errno -2] Name or service not known')': /vectors/upsert
[2024-10-07T06:16:47.884+0000] {logging_mixin.py:137} INFO - Failed to process /tmp/pymupdf_example.pdf.json: HTTPSConnectionPool(host='pymupdf-index-unknown.svc.us-east1-aws.pinecone.io', port=443): Max retries exceeded with url: /vectors/upsert (Caused by NewConnectionError('<urllib3.connection.HTTPSConnection object at 0x7faefba02050>: Failed to establish a new connection: [Errno -2] Name or service not known'))
[2024-10-07T06:16:47.884+0000] {python.py:177} INFO - Done. Returned value was: None
[2024-10-07T06:16:47.908+0000] {taskinstance.py:1327} INFO - Marking task as SUCCESS. dag_id=pinecone_embedding_test_dag, task_id=embed_pymupdf_pages, execution_date=20241007T061500, start_date=20241007T061513, end_date=20241007T061647
[2024-10-07T06:16:47.937+0000] {local_task_job.py:159} INFO - Task exited with return code 0
[2024-10-07T06:16:47.971+0000] {taskinstance.py:2582} INFO - 0 downstream tasks scheduled from follow-on schedule check
