[2024-10-07T05:47:19.319+0000] {taskinstance.py:1087} INFO - Dependencies all met for <TaskInstance: pdf_extraction_with_pymupdf_and_convertapi_and_embeddings.embed_and_store_pdf_pages manual__2024-10-07T05:46:56.228733+00:00 [queued]>
[2024-10-07T05:47:19.334+0000] {taskinstance.py:1087} INFO - Dependencies all met for <TaskInstance: pdf_extraction_with_pymupdf_and_convertapi_and_embeddings.embed_and_store_pdf_pages manual__2024-10-07T05:46:56.228733+00:00 [queued]>
[2024-10-07T05:47:19.335+0000] {taskinstance.py:1283} INFO - 
--------------------------------------------------------------------------------
[2024-10-07T05:47:19.335+0000] {taskinstance.py:1284} INFO - Starting attempt 1 of 3
[2024-10-07T05:47:19.336+0000] {taskinstance.py:1285} INFO - 
--------------------------------------------------------------------------------
[2024-10-07T05:47:19.360+0000] {taskinstance.py:1304} INFO - Executing <Task(PythonOperator): embed_and_store_pdf_pages> on 2024-10-07 05:46:56.228733+00:00
[2024-10-07T05:47:19.368+0000] {standard_task_runner.py:55} INFO - Started process 5438 to run task
[2024-10-07T05:47:19.371+0000] {standard_task_runner.py:82} INFO - Running: ['***', 'tasks', 'run', 'pdf_extraction_with_pymupdf_and_convertapi_and_embeddings', 'embed_and_store_pdf_pages', 'manual__2024-10-07T05:46:56.228733+00:00', '--job-id', '375', '--raw', '--subdir', 'DAGS_FOLDER/ETL-ConvertAPI.py', '--cfg-path', '/tmp/tmpu0zp7tjm']
[2024-10-07T05:47:19.371+0000] {standard_task_runner.py:83} INFO - Job 375: Subtask embed_and_store_pdf_pages
[2024-10-07T05:47:19.403+0000] {logging_mixin.py:137} WARNING - /home/***/.local/lib/python3.7/site-packages/***/settings.py:249 DeprecationWarning: The sql_alchemy_conn option in [core] has been moved to the sql_alchemy_conn option in [database] - the old setting has been used, but please update your config.
[2024-10-07T05:47:19.496+0000] {task_command.py:389} INFO - Running <TaskInstance: pdf_extraction_with_pymupdf_and_convertapi_and_embeddings.embed_and_store_pdf_pages manual__2024-10-07T05:46:56.228733+00:00 [running]> on host 1350c74cd1fb
[2024-10-07T05:47:19.604+0000] {taskinstance.py:1513} INFO - Exporting the following env vars:
AIRFLOW_CTX_DAG_OWNER=***
AIRFLOW_CTX_DAG_ID=pdf_extraction_with_pymupdf_and_convertapi_and_embeddings
AIRFLOW_CTX_TASK_ID=embed_and_store_pdf_pages
AIRFLOW_CTX_EXECUTION_DATE=2024-10-07T05:46:56.228733+00:00
AIRFLOW_CTX_TRY_NUMBER=1
AIRFLOW_CTX_DAG_RUN_ID=manual__2024-10-07T05:46:56.228733+00:00
[2024-10-07T05:47:19.611+0000] {connectionpool.py:813} WARNING - Retrying (Retry(total=2, connect=None, read=None, redirect=None, status=None)) after connection broken by 'NewConnectionError('<urllib3.connection.HTTPSConnection object at 0x7f47ba1ff2d0>: Failed to establish a new connection: [Errno -2] Name or service not known')': /databases
[2024-10-07T05:47:19.614+0000] {connectionpool.py:813} WARNING - Retrying (Retry(total=1, connect=None, read=None, redirect=None, status=None)) after connection broken by 'NewConnectionError('<urllib3.connection.HTTPSConnection object at 0x7f47ba1ff750>: Failed to establish a new connection: [Errno -2] Name or service not known')': /databases
[2024-10-07T05:47:19.617+0000] {connectionpool.py:813} WARNING - Retrying (Retry(total=0, connect=None, read=None, redirect=None, status=None)) after connection broken by 'NewConnectionError('<urllib3.connection.HTTPSConnection object at 0x7f47ba1ff710>: Failed to establish a new connection: [Errno -2] Name or service not known')': /databases
[2024-10-07T05:47:19.620+0000] {logging_mixin.py:137} INFO - Failed to create Pinecone index: HTTPSConnectionPool(host='controller.us-east1-aws.pinecone.io', port=443): Max retries exceeded with url: /databases (Caused by NewConnectionError('<urllib3.connection.HTTPSConnection object at 0x7f47ba1ff950>: Failed to establish a new connection: [Errno -2] Name or service not known'))
[2024-10-07T05:47:19.624+0000] {connectionpool.py:813} WARNING - Retrying (Retry(total=2, connect=None, read=None, redirect=None, status=None)) after connection broken by 'NewConnectionError('<urllib3.connection.HTTPSConnection object at 0x7f47ba23ffd0>: Failed to establish a new connection: [Errno -2] Name or service not known')': /databases
[2024-10-07T05:47:19.626+0000] {connectionpool.py:813} WARNING - Retrying (Retry(total=1, connect=None, read=None, redirect=None, status=None)) after connection broken by 'NewConnectionError('<urllib3.connection.HTTPSConnection object at 0x7f47ba1ffb50>: Failed to establish a new connection: [Errno -2] Name or service not known')': /databases
[2024-10-07T05:47:19.629+0000] {connectionpool.py:813} WARNING - Retrying (Retry(total=0, connect=None, read=None, redirect=None, status=None)) after connection broken by 'NewConnectionError('<urllib3.connection.HTTPSConnection object at 0x7f47ba1ff3d0>: Failed to establish a new connection: [Errno -2] Name or service not known')': /databases
[2024-10-07T05:47:19.632+0000] {logging_mixin.py:137} INFO - Failed to create Pinecone index: HTTPSConnectionPool(host='controller.us-east1-aws.pinecone.io', port=443): Max retries exceeded with url: /databases (Caused by NewConnectionError('<urllib3.connection.HTTPSConnection object at 0x7f47ba1ff650>: Failed to establish a new connection: [Errno -2] Name or service not known'))
[2024-10-07T05:47:19.775+0000] {python.py:177} INFO - Done. Returned value was: None
[2024-10-07T05:47:19.794+0000] {taskinstance.py:1327} INFO - Marking task as SUCCESS. dag_id=pdf_extraction_with_pymupdf_and_convertapi_and_embeddings, task_id=embed_and_store_pdf_pages, execution_date=20241007T054656, start_date=20241007T054719, end_date=20241007T054719
[2024-10-07T05:47:19.824+0000] {local_task_job.py:159} INFO - Task exited with return code 0
[2024-10-07T05:47:19.858+0000] {taskinstance.py:2582} INFO - 0 downstream tasks scheduled from follow-on schedule check
