[2024-10-07T06:22:18.974+0000] {taskinstance.py:1087} INFO - Dependencies all met for <TaskInstance: pinecone_embedding_test_dag.embed_pymupdf_pages manual__2024-10-07T06:17:05.922519+00:00 [queued]>
[2024-10-07T06:22:19.091+0000] {taskinstance.py:1087} INFO - Dependencies all met for <TaskInstance: pinecone_embedding_test_dag.embed_pymupdf_pages manual__2024-10-07T06:17:05.922519+00:00 [queued]>
[2024-10-07T06:22:19.092+0000] {taskinstance.py:1283} INFO - 
--------------------------------------------------------------------------------
[2024-10-07T06:22:19.092+0000] {taskinstance.py:1284} INFO - Starting attempt 2 of 3
[2024-10-07T06:22:19.092+0000] {taskinstance.py:1285} INFO - 
--------------------------------------------------------------------------------
[2024-10-07T06:22:19.109+0000] {taskinstance.py:1304} INFO - Executing <Task(PythonOperator): embed_pymupdf_pages> on 2024-10-07 06:17:05.922519+00:00
[2024-10-07T06:22:19.115+0000] {standard_task_runner.py:55} INFO - Started process 846 to run task
[2024-10-07T06:22:19.119+0000] {standard_task_runner.py:82} INFO - Running: ['***', 'tasks', 'run', 'pinecone_embedding_test_dag', 'embed_pymupdf_pages', 'manual__2024-10-07T06:17:05.922519+00:00', '--job-id', '410', '--raw', '--subdir', 'DAGS_FOLDER/Pinecone_Test.py', '--cfg-path', '/tmp/tmpspjnemsm']
[2024-10-07T06:22:19.119+0000] {standard_task_runner.py:83} INFO - Job 410: Subtask embed_pymupdf_pages
[2024-10-07T06:22:19.143+0000] {logging_mixin.py:137} WARNING - /home/***/.local/lib/python3.7/site-packages/***/settings.py:249 DeprecationWarning: The sql_alchemy_conn option in [core] has been moved to the sql_alchemy_conn option in [database] - the old setting has been used, but please update your config.
[2024-10-07T06:22:19.225+0000] {task_command.py:389} INFO - Running <TaskInstance: pinecone_embedding_test_dag.embed_pymupdf_pages manual__2024-10-07T06:17:05.922519+00:00 [running]> on host 2478cb613add
[2024-10-07T06:22:19.335+0000] {taskinstance.py:1513} INFO - Exporting the following env vars:
AIRFLOW_CTX_DAG_OWNER=***
AIRFLOW_CTX_DAG_ID=pinecone_embedding_test_dag
AIRFLOW_CTX_TASK_ID=embed_pymupdf_pages
AIRFLOW_CTX_EXECUTION_DATE=2024-10-07T06:17:05.922519+00:00
AIRFLOW_CTX_TRY_NUMBER=2
AIRFLOW_CTX_DAG_RUN_ID=manual__2024-10-07T06:17:05.922519+00:00
[2024-10-07T06:22:19.367+0000] {connectionpool.py:813} WARNING - Retrying (Retry(total=2, connect=None, read=None, redirect=None, status=None)) after connection broken by 'NewConnectionError('<urllib3.connection.HTTPSConnection object at 0x7faefbacf150>: Failed to establish a new connection: [Errno -2] Name or service not known')': /databases
[2024-10-07T06:22:19.370+0000] {connectionpool.py:813} WARNING - Retrying (Retry(total=1, connect=None, read=None, redirect=None, status=None)) after connection broken by 'NewConnectionError('<urllib3.connection.HTTPSConnection object at 0x7faefbacf310>: Failed to establish a new connection: [Errno -2] Name or service not known')': /databases
[2024-10-07T06:22:19.375+0000] {connectionpool.py:813} WARNING - Retrying (Retry(total=0, connect=None, read=None, redirect=None, status=None)) after connection broken by 'NewConnectionError('<urllib3.connection.HTTPSConnection object at 0x7faefbacf410>: Failed to establish a new connection: [Errno -2] Name or service not known')': /databases
[2024-10-07T06:22:19.377+0000] {logging_mixin.py:137} INFO - Error creating Pinecone index: HTTPSConnectionPool(host='controller.us-east1-aws.pinecone.io', port=443): Max retries exceeded with url: /databases (Caused by NewConnectionError('<urllib3.connection.HTTPSConnection object at 0x7faefbacf6d0>: Failed to establish a new connection: [Errno -2] Name or service not known'))
[2024-10-07T06:22:19.746+0000] {connectionpool.py:813} WARNING - Retrying (Retry(total=2, connect=None, read=None, redirect=None, status=None)) after connection broken by 'NewConnectionError('<urllib3.connection.HTTPSConnection object at 0x7faefbadf150>: Failed to establish a new connection: [Errno -2] Name or service not known')': /vectors/upsert
[2024-10-07T06:22:19.750+0000] {connectionpool.py:813} WARNING - Retrying (Retry(total=1, connect=None, read=None, redirect=None, status=None)) after connection broken by 'NewConnectionError('<urllib3.connection.HTTPSConnection object at 0x7faefba604d0>: Failed to establish a new connection: [Errno -2] Name or service not known')': /vectors/upsert
[2024-10-07T06:22:19.752+0000] {connectionpool.py:813} WARNING - Retrying (Retry(total=0, connect=None, read=None, redirect=None, status=None)) after connection broken by 'NewConnectionError('<urllib3.connection.HTTPSConnection object at 0x7faefba87c50>: Failed to establish a new connection: [Errno -2] Name or service not known')': /vectors/upsert
[2024-10-07T06:22:19.754+0000] {logging_mixin.py:137} INFO - Failed to process /tmp/pymupdf_021a5339-744f-42b7-bd9b-9368b3efda7a.pdf.json: HTTPSConnectionPool(host='pymupdf-index-unknown.svc.us-east1-aws.pinecone.io', port=443): Max retries exceeded with url: /vectors/upsert (Caused by NewConnectionError('<urllib3.connection.HTTPSConnection object at 0x7faefbb80110>: Failed to establish a new connection: [Errno -2] Name or service not known'))
[2024-10-07T06:22:20.213+0000] {connectionpool.py:813} WARNING - Retrying (Retry(total=2, connect=None, read=None, redirect=None, status=None)) after connection broken by 'NewConnectionError('<urllib3.connection.HTTPSConnection object at 0x7faefbacf850>: Failed to establish a new connection: [Errno -2] Name or service not known')': /vectors/upsert
[2024-10-07T06:22:20.216+0000] {connectionpool.py:813} WARNING - Retrying (Retry(total=1, connect=None, read=None, redirect=None, status=None)) after connection broken by 'NewConnectionError('<urllib3.connection.HTTPSConnection object at 0x7faefba9e8d0>: Failed to establish a new connection: [Errno -2] Name or service not known')': /vectors/upsert
[2024-10-07T06:22:20.218+0000] {connectionpool.py:813} WARNING - Retrying (Retry(total=0, connect=None, read=None, redirect=None, status=None)) after connection broken by 'NewConnectionError('<urllib3.connection.HTTPSConnection object at 0x7faefba604d0>: Failed to establish a new connection: [Errno -2] Name or service not known')': /vectors/upsert
[2024-10-07T06:22:20.220+0000] {logging_mixin.py:137} INFO - Failed to process /tmp/pymupdf_366e2f2b-8632-4ef2-81eb-bc3877489217.pdf.json: HTTPSConnectionPool(host='pymupdf-index-unknown.svc.us-east1-aws.pinecone.io', port=443): Max retries exceeded with url: /vectors/upsert (Caused by NewConnectionError('<urllib3.connection.HTTPSConnection object at 0x7faefba87b90>: Failed to establish a new connection: [Errno -2] Name or service not known'))
[2024-10-07T06:22:20.404+0000] {connectionpool.py:813} WARNING - Retrying (Retry(total=2, connect=None, read=None, redirect=None, status=None)) after connection broken by 'NewConnectionError('<urllib3.connection.HTTPSConnection object at 0x7faefba041d0>: Failed to establish a new connection: [Errno -2] Name or service not known')': /vectors/upsert
[2024-10-07T06:22:20.406+0000] {connectionpool.py:813} WARNING - Retrying (Retry(total=1, connect=None, read=None, redirect=None, status=None)) after connection broken by 'NewConnectionError('<urllib3.connection.HTTPSConnection object at 0x7faefba04590>: Failed to establish a new connection: [Errno -2] Name or service not known')': /vectors/upsert
[2024-10-07T06:22:20.409+0000] {connectionpool.py:813} WARNING - Retrying (Retry(total=0, connect=None, read=None, redirect=None, status=None)) after connection broken by 'NewConnectionError('<urllib3.connection.HTTPSConnection object at 0x7faefba044d0>: Failed to establish a new connection: [Errno -2] Name or service not known')': /vectors/upsert
[2024-10-07T06:22:20.412+0000] {logging_mixin.py:137} INFO - Failed to process /tmp/pymupdf_634fca59-03b2-4cdf-9ce4-0205df22f256.pdf.json: HTTPSConnectionPool(host='pymupdf-index-unknown.svc.us-east1-aws.pinecone.io', port=443): Max retries exceeded with url: /vectors/upsert (Caused by NewConnectionError('<urllib3.connection.HTTPSConnection object at 0x7faefbaa6a50>: Failed to establish a new connection: [Errno -2] Name or service not known'))
[2024-10-07T06:22:20.600+0000] {connectionpool.py:813} WARNING - Retrying (Retry(total=2, connect=None, read=None, redirect=None, status=None)) after connection broken by 'NewConnectionError('<urllib3.connection.HTTPSConnection object at 0x7faefb9a91d0>: Failed to establish a new connection: [Errno -2] Name or service not known')': /vectors/upsert
[2024-10-07T06:22:20.603+0000] {connectionpool.py:813} WARNING - Retrying (Retry(total=1, connect=None, read=None, redirect=None, status=None)) after connection broken by 'NewConnectionError('<urllib3.connection.HTTPSConnection object at 0x7faefba043d0>: Failed to establish a new connection: [Errno -2] Name or service not known')': /vectors/upsert
[2024-10-07T06:22:20.605+0000] {connectionpool.py:813} WARNING - Retrying (Retry(total=0, connect=None, read=None, redirect=None, status=None)) after connection broken by 'NewConnectionError('<urllib3.connection.HTTPSConnection object at 0x7faefbabff90>: Failed to establish a new connection: [Errno -2] Name or service not known')': /vectors/upsert
[2024-10-07T06:22:20.607+0000] {logging_mixin.py:137} INFO - Failed to process /tmp/pymupdf_8f697523-6988-4c4f-8d72-760a45681f68.pdf.json: HTTPSConnectionPool(host='pymupdf-index-unknown.svc.us-east1-aws.pinecone.io', port=443): Max retries exceeded with url: /vectors/upsert (Caused by NewConnectionError('<urllib3.connection.HTTPSConnection object at 0x7faefba24910>: Failed to establish a new connection: [Errno -2] Name or service not known'))
[2024-10-07T06:22:22.217+0000] {connectionpool.py:813} WARNING - Retrying (Retry(total=2, connect=None, read=None, redirect=None, status=None)) after connection broken by 'NewConnectionError('<urllib3.connection.HTTPSConnection object at 0x7faefba7c290>: Failed to establish a new connection: [Errno -2] Name or service not known')': /vectors/upsert
[2024-10-07T06:22:22.219+0000] {connectionpool.py:813} WARNING - Retrying (Retry(total=1, connect=None, read=None, redirect=None, status=None)) after connection broken by 'NewConnectionError('<urllib3.connection.HTTPSConnection object at 0x7faefba7cb10>: Failed to establish a new connection: [Errno -2] Name or service not known')': /vectors/upsert
[2024-10-07T06:22:22.223+0000] {connectionpool.py:813} WARNING - Retrying (Retry(total=0, connect=None, read=None, redirect=None, status=None)) after connection broken by 'NewConnectionError('<urllib3.connection.HTTPSConnection object at 0x7faefba7c490>: Failed to establish a new connection: [Errno -2] Name or service not known')': /vectors/upsert
[2024-10-07T06:22:22.225+0000] {logging_mixin.py:137} INFO - Failed to process /tmp/pymupdf_example.pdf.json: HTTPSConnectionPool(host='pymupdf-index-unknown.svc.us-east1-aws.pinecone.io', port=443): Max retries exceeded with url: /vectors/upsert (Caused by NewConnectionError('<urllib3.connection.HTTPSConnection object at 0x7faefba7fe90>: Failed to establish a new connection: [Errno -2] Name or service not known'))
[2024-10-07T06:22:22.226+0000] {python.py:177} INFO - Done. Returned value was: None
[2024-10-07T06:22:22.245+0000] {taskinstance.py:1327} INFO - Marking task as SUCCESS. dag_id=pinecone_embedding_test_dag, task_id=embed_pymupdf_pages, execution_date=20241007T061705, start_date=20241007T062218, end_date=20241007T062222
[2024-10-07T06:22:22.302+0000] {local_task_job.py:159} INFO - Task exited with return code 0
[2024-10-07T06:22:22.329+0000] {taskinstance.py:2582} INFO - 0 downstream tasks scheduled from follow-on schedule check
