[2024-10-07T06:19:35.126+0000] {taskinstance.py:1087} INFO - Dependencies all met for <TaskInstance: pinecone_embedding_test_dag.embed_pymupdf_pages manual__2024-10-07T06:19:22.937602+00:00 [queued]>
[2024-10-07T06:19:35.300+0000] {taskinstance.py:1087} INFO - Dependencies all met for <TaskInstance: pinecone_embedding_test_dag.embed_pymupdf_pages manual__2024-10-07T06:19:22.937602+00:00 [queued]>
[2024-10-07T06:19:35.301+0000] {taskinstance.py:1283} INFO - 
--------------------------------------------------------------------------------
[2024-10-07T06:19:35.301+0000] {taskinstance.py:1284} INFO - Starting attempt 1 of 3
[2024-10-07T06:19:35.301+0000] {taskinstance.py:1285} INFO - 
--------------------------------------------------------------------------------
[2024-10-07T06:19:35.318+0000] {taskinstance.py:1304} INFO - Executing <Task(PythonOperator): embed_pymupdf_pages> on 2024-10-07 06:19:22.937602+00:00
[2024-10-07T06:19:35.330+0000] {standard_task_runner.py:55} INFO - Started process 742 to run task
[2024-10-07T06:19:35.333+0000] {standard_task_runner.py:82} INFO - Running: ['***', 'tasks', 'run', 'pinecone_embedding_test_dag', 'embed_pymupdf_pages', 'manual__2024-10-07T06:19:22.937602+00:00', '--job-id', '408', '--raw', '--subdir', 'DAGS_FOLDER/Pinecone_Test.py', '--cfg-path', '/tmp/tmpvjl_k0xu']
[2024-10-07T06:19:35.334+0000] {standard_task_runner.py:83} INFO - Job 408: Subtask embed_pymupdf_pages
[2024-10-07T06:19:35.366+0000] {logging_mixin.py:137} WARNING - /home/***/.local/lib/python3.7/site-packages/***/settings.py:249 DeprecationWarning: The sql_alchemy_conn option in [core] has been moved to the sql_alchemy_conn option in [database] - the old setting has been used, but please update your config.
[2024-10-07T06:19:35.485+0000] {task_command.py:389} INFO - Running <TaskInstance: pinecone_embedding_test_dag.embed_pymupdf_pages manual__2024-10-07T06:19:22.937602+00:00 [running]> on host 2478cb613add
[2024-10-07T06:19:35.641+0000] {taskinstance.py:1513} INFO - Exporting the following env vars:
AIRFLOW_CTX_DAG_OWNER=***
AIRFLOW_CTX_DAG_ID=pinecone_embedding_test_dag
AIRFLOW_CTX_TASK_ID=embed_pymupdf_pages
AIRFLOW_CTX_EXECUTION_DATE=2024-10-07T06:19:22.937602+00:00
AIRFLOW_CTX_TRY_NUMBER=1
AIRFLOW_CTX_DAG_RUN_ID=manual__2024-10-07T06:19:22.937602+00:00
[2024-10-07T06:19:35.681+0000] {connectionpool.py:813} WARNING - Retrying (Retry(total=2, connect=None, read=None, redirect=None, status=None)) after connection broken by 'NewConnectionError('<urllib3.connection.HTTPSConnection object at 0x7faefbac0a90>: Failed to establish a new connection: [Errno -2] Name or service not known')': /databases
[2024-10-07T06:19:35.684+0000] {connectionpool.py:813} WARNING - Retrying (Retry(total=1, connect=None, read=None, redirect=None, status=None)) after connection broken by 'NewConnectionError('<urllib3.connection.HTTPSConnection object at 0x7faefbac0e10>: Failed to establish a new connection: [Errno -2] Name or service not known')': /databases
[2024-10-07T06:19:35.688+0000] {connectionpool.py:813} WARNING - Retrying (Retry(total=0, connect=None, read=None, redirect=None, status=None)) after connection broken by 'NewConnectionError('<urllib3.connection.HTTPSConnection object at 0x7faefbad3050>: Failed to establish a new connection: [Errno -2] Name or service not known')': /databases
[2024-10-07T06:19:35.694+0000] {logging_mixin.py:137} INFO - Error creating Pinecone index: HTTPSConnectionPool(host='controller.us-east1-aws.pinecone.io', port=443): Max retries exceeded with url: /databases (Caused by NewConnectionError('<urllib3.connection.HTTPSConnection object at 0x7faefbad3190>: Failed to establish a new connection: [Errno -2] Name or service not known'))
[2024-10-07T06:19:36.834+0000] {connectionpool.py:813} WARNING - Retrying (Retry(total=2, connect=None, read=None, redirect=None, status=None)) after connection broken by 'NewConnectionError('<urllib3.connection.HTTPSConnection object at 0x7faefba6ab90>: Failed to establish a new connection: [Errno -2] Name or service not known')': /vectors/upsert
[2024-10-07T06:19:36.838+0000] {connectionpool.py:813} WARNING - Retrying (Retry(total=1, connect=None, read=None, redirect=None, status=None)) after connection broken by 'NewConnectionError('<urllib3.connection.HTTPSConnection object at 0x7faefba71ad0>: Failed to establish a new connection: [Errno -2] Name or service not known')': /vectors/upsert
[2024-10-07T06:19:36.842+0000] {connectionpool.py:813} WARNING - Retrying (Retry(total=0, connect=None, read=None, redirect=None, status=None)) after connection broken by 'NewConnectionError('<urllib3.connection.HTTPSConnection object at 0x7faefba91a50>: Failed to establish a new connection: [Errno -2] Name or service not known')': /vectors/upsert
[2024-10-07T06:19:36.846+0000] {logging_mixin.py:137} INFO - Failed to process /tmp/pymupdf_021a5339-744f-42b7-bd9b-9368b3efda7a.pdf.json: HTTPSConnectionPool(host='pymupdf-index-unknown.svc.us-east1-aws.pinecone.io', port=443): Max retries exceeded with url: /vectors/upsert (Caused by NewConnectionError('<urllib3.connection.HTTPSConnection object at 0x7faefbadaf10>: Failed to establish a new connection: [Errno -2] Name or service not known'))
[2024-10-07T06:19:37.190+0000] {connectionpool.py:813} WARNING - Retrying (Retry(total=2, connect=None, read=None, redirect=None, status=None)) after connection broken by 'NewConnectionError('<urllib3.connection.HTTPSConnection object at 0x7faefba29cd0>: Failed to establish a new connection: [Errno -2] Name or service not known')': /vectors/upsert
[2024-10-07T06:19:37.193+0000] {connectionpool.py:813} WARNING - Retrying (Retry(total=1, connect=None, read=None, redirect=None, status=None)) after connection broken by 'NewConnectionError('<urllib3.connection.HTTPSConnection object at 0x7faefba3b1d0>: Failed to establish a new connection: [Errno -2] Name or service not known')': /vectors/upsert
[2024-10-07T06:19:37.197+0000] {connectionpool.py:813} WARNING - Retrying (Retry(total=0, connect=None, read=None, redirect=None, status=None)) after connection broken by 'NewConnectionError('<urllib3.connection.HTTPSConnection object at 0x7faefb9b0f10>: Failed to establish a new connection: [Errno -2] Name or service not known')': /vectors/upsert
[2024-10-07T06:19:37.201+0000] {logging_mixin.py:137} INFO - Failed to process /tmp/pymupdf_366e2f2b-8632-4ef2-81eb-bc3877489217.pdf.json: HTTPSConnectionPool(host='pymupdf-index-unknown.svc.us-east1-aws.pinecone.io', port=443): Max retries exceeded with url: /vectors/upsert (Caused by NewConnectionError('<urllib3.connection.HTTPSConnection object at 0x7faefba81110>: Failed to establish a new connection: [Errno -2] Name or service not known'))
[2024-10-07T06:19:37.534+0000] {connectionpool.py:813} WARNING - Retrying (Retry(total=2, connect=None, read=None, redirect=None, status=None)) after connection broken by 'NewConnectionError('<urllib3.connection.HTTPSConnection object at 0x7faefb9ab410>: Failed to establish a new connection: [Errno -2] Name or service not known')': /vectors/upsert
[2024-10-07T06:19:37.538+0000] {connectionpool.py:813} WARNING - Retrying (Retry(total=1, connect=None, read=None, redirect=None, status=None)) after connection broken by 'NewConnectionError('<urllib3.connection.HTTPSConnection object at 0x7faefbadaa90>: Failed to establish a new connection: [Errno -2] Name or service not known')': /vectors/upsert
[2024-10-07T06:19:37.543+0000] {connectionpool.py:813} WARNING - Retrying (Retry(total=0, connect=None, read=None, redirect=None, status=None)) after connection broken by 'NewConnectionError('<urllib3.connection.HTTPSConnection object at 0x7faefba18b50>: Failed to establish a new connection: [Errno -2] Name or service not known')': /vectors/upsert
[2024-10-07T06:19:37.546+0000] {logging_mixin.py:137} INFO - Failed to process /tmp/pymupdf_634fca59-03b2-4cdf-9ce4-0205df22f256.pdf.json: HTTPSConnectionPool(host='pymupdf-index-unknown.svc.us-east1-aws.pinecone.io', port=443): Max retries exceeded with url: /vectors/upsert (Caused by NewConnectionError('<urllib3.connection.HTTPSConnection object at 0x7faefbadac90>: Failed to establish a new connection: [Errno -2] Name or service not known'))
[2024-10-07T06:19:38.036+0000] {connectionpool.py:813} WARNING - Retrying (Retry(total=2, connect=None, read=None, redirect=None, status=None)) after connection broken by 'NewConnectionError('<urllib3.connection.HTTPSConnection object at 0x7faefba18950>: Failed to establish a new connection: [Errno -2] Name or service not known')': /vectors/upsert
[2024-10-07T06:19:38.041+0000] {connectionpool.py:813} WARNING - Retrying (Retry(total=1, connect=None, read=None, redirect=None, status=None)) after connection broken by 'NewConnectionError('<urllib3.connection.HTTPSConnection object at 0x7faefbac0d10>: Failed to establish a new connection: [Errno -2] Name or service not known')': /vectors/upsert
[2024-10-07T06:19:38.046+0000] {connectionpool.py:813} WARNING - Retrying (Retry(total=0, connect=None, read=None, redirect=None, status=None)) after connection broken by 'NewConnectionError('<urllib3.connection.HTTPSConnection object at 0x7faefba6a910>: Failed to establish a new connection: [Errno -2] Name or service not known')': /vectors/upsert
[2024-10-07T06:19:38.050+0000] {logging_mixin.py:137} INFO - Failed to process /tmp/pymupdf_8f697523-6988-4c4f-8d72-760a45681f68.pdf.json: HTTPSConnectionPool(host='pymupdf-index-unknown.svc.us-east1-aws.pinecone.io', port=443): Max retries exceeded with url: /vectors/upsert (Caused by NewConnectionError('<urllib3.connection.HTTPSConnection object at 0x7faefba3b3d0>: Failed to establish a new connection: [Errno -2] Name or service not known'))
[2024-10-07T06:19:39.480+0000] {connectionpool.py:813} WARNING - Retrying (Retry(total=2, connect=None, read=None, redirect=None, status=None)) after connection broken by 'NewConnectionError('<urllib3.connection.HTTPSConnection object at 0x7faefba1bad0>: Failed to establish a new connection: [Errno -2] Name or service not known')': /vectors/upsert
[2024-10-07T06:19:39.483+0000] {connectionpool.py:813} WARNING - Retrying (Retry(total=1, connect=None, read=None, redirect=None, status=None)) after connection broken by 'NewConnectionError('<urllib3.connection.HTTPSConnection object at 0x7faefba1bb10>: Failed to establish a new connection: [Errno -2] Name or service not known')': /vectors/upsert
[2024-10-07T06:19:39.487+0000] {connectionpool.py:813} WARNING - Retrying (Retry(total=0, connect=None, read=None, redirect=None, status=None)) after connection broken by 'NewConnectionError('<urllib3.connection.HTTPSConnection object at 0x7faefba6a390>: Failed to establish a new connection: [Errno -2] Name or service not known')': /vectors/upsert
[2024-10-07T06:19:39.490+0000] {logging_mixin.py:137} INFO - Failed to process /tmp/pymupdf_example.pdf.json: HTTPSConnectionPool(host='pymupdf-index-unknown.svc.us-east1-aws.pinecone.io', port=443): Max retries exceeded with url: /vectors/upsert (Caused by NewConnectionError('<urllib3.connection.HTTPSConnection object at 0x7faefbaa0f10>: Failed to establish a new connection: [Errno -2] Name or service not known'))
[2024-10-07T06:19:39.491+0000] {python.py:177} INFO - Done. Returned value was: None
[2024-10-07T06:19:39.528+0000] {taskinstance.py:1327} INFO - Marking task as SUCCESS. dag_id=pinecone_embedding_test_dag, task_id=embed_pymupdf_pages, execution_date=20241007T061922, start_date=20241007T061935, end_date=20241007T061939
[2024-10-07T06:19:39.562+0000] {local_task_job.py:159} INFO - Task exited with return code 0
[2024-10-07T06:19:39.602+0000] {taskinstance.py:2582} INFO - 0 downstream tasks scheduled from follow-on schedule check
