[2024-10-07T06:19:35.126+0000] {taskinstance.py:1087} INFO - Dependencies all met for <TaskInstance: pinecone_embedding_test_dag.embed_convertapi_pages manual__2024-10-07T06:19:22.937602+00:00 [queued]>
[2024-10-07T06:19:35.305+0000] {taskinstance.py:1087} INFO - Dependencies all met for <TaskInstance: pinecone_embedding_test_dag.embed_convertapi_pages manual__2024-10-07T06:19:22.937602+00:00 [queued]>
[2024-10-07T06:19:35.305+0000] {taskinstance.py:1283} INFO - 
--------------------------------------------------------------------------------
[2024-10-07T06:19:35.306+0000] {taskinstance.py:1284} INFO - Starting attempt 1 of 3
[2024-10-07T06:19:35.306+0000] {taskinstance.py:1285} INFO - 
--------------------------------------------------------------------------------
[2024-10-07T06:19:35.331+0000] {taskinstance.py:1304} INFO - Executing <Task(PythonOperator): embed_convertapi_pages> on 2024-10-07 06:19:22.937602+00:00
[2024-10-07T06:19:35.338+0000] {standard_task_runner.py:55} INFO - Started process 743 to run task
[2024-10-07T06:19:35.341+0000] {standard_task_runner.py:82} INFO - Running: ['***', 'tasks', 'run', 'pinecone_embedding_test_dag', 'embed_convertapi_pages', 'manual__2024-10-07T06:19:22.937602+00:00', '--job-id', '407', '--raw', '--subdir', 'DAGS_FOLDER/Pinecone_Test.py', '--cfg-path', '/tmp/tmps19o7ii4']
[2024-10-07T06:19:35.342+0000] {standard_task_runner.py:83} INFO - Job 407: Subtask embed_convertapi_pages
[2024-10-07T06:19:35.379+0000] {logging_mixin.py:137} WARNING - /home/***/.local/lib/python3.7/site-packages/***/settings.py:249 DeprecationWarning: The sql_alchemy_conn option in [core] has been moved to the sql_alchemy_conn option in [database] - the old setting has been used, but please update your config.
[2024-10-07T06:19:35.501+0000] {task_command.py:389} INFO - Running <TaskInstance: pinecone_embedding_test_dag.embed_convertapi_pages manual__2024-10-07T06:19:22.937602+00:00 [running]> on host 2478cb613add
[2024-10-07T06:19:35.656+0000] {taskinstance.py:1513} INFO - Exporting the following env vars:
AIRFLOW_CTX_DAG_OWNER=***
AIRFLOW_CTX_DAG_ID=pinecone_embedding_test_dag
AIRFLOW_CTX_TASK_ID=embed_convertapi_pages
AIRFLOW_CTX_EXECUTION_DATE=2024-10-07T06:19:22.937602+00:00
AIRFLOW_CTX_TRY_NUMBER=1
AIRFLOW_CTX_DAG_RUN_ID=manual__2024-10-07T06:19:22.937602+00:00
[2024-10-07T06:19:35.701+0000] {connectionpool.py:813} WARNING - Retrying (Retry(total=2, connect=None, read=None, redirect=None, status=None)) after connection broken by 'NewConnectionError('<urllib3.connection.HTTPSConnection object at 0x7faefbac1b10>: Failed to establish a new connection: [Errno -2] Name or service not known')': /databases
[2024-10-07T06:19:35.706+0000] {connectionpool.py:813} WARNING - Retrying (Retry(total=1, connect=None, read=None, redirect=None, status=None)) after connection broken by 'NewConnectionError('<urllib3.connection.HTTPSConnection object at 0x7faefbac1e90>: Failed to establish a new connection: [Errno -2] Name or service not known')': /databases
[2024-10-07T06:19:35.709+0000] {connectionpool.py:813} WARNING - Retrying (Retry(total=0, connect=None, read=None, redirect=None, status=None)) after connection broken by 'NewConnectionError('<urllib3.connection.HTTPSConnection object at 0x7faefbad3050>: Failed to establish a new connection: [Errno -2] Name or service not known')': /databases
[2024-10-07T06:19:35.713+0000] {logging_mixin.py:137} INFO - Error creating Pinecone index: HTTPSConnectionPool(host='controller.us-east1-aws.pinecone.io', port=443): Max retries exceeded with url: /databases (Caused by NewConnectionError('<urllib3.connection.HTTPSConnection object at 0x7faefbad3210>: Failed to establish a new connection: [Errno -2] Name or service not known'))
[2024-10-07T06:19:36.392+0000] {connectionpool.py:813} WARNING - Retrying (Retry(total=2, connect=None, read=None, redirect=None, status=None)) after connection broken by 'NewConnectionError('<urllib3.connection.HTTPSConnection object at 0x7faefba713d0>: Failed to establish a new connection: [Errno -2] Name or service not known')': /vectors/upsert
[2024-10-07T06:19:36.396+0000] {connectionpool.py:813} WARNING - Retrying (Retry(total=1, connect=None, read=None, redirect=None, status=None)) after connection broken by 'NewConnectionError('<urllib3.connection.HTTPSConnection object at 0x7faefba896d0>: Failed to establish a new connection: [Errno -2] Name or service not known')': /vectors/upsert
[2024-10-07T06:19:36.399+0000] {connectionpool.py:813} WARNING - Retrying (Retry(total=0, connect=None, read=None, redirect=None, status=None)) after connection broken by 'NewConnectionError('<urllib3.connection.HTTPSConnection object at 0x7faefba89410>: Failed to establish a new connection: [Errno -2] Name or service not known')': /vectors/upsert
[2024-10-07T06:19:36.403+0000] {logging_mixin.py:137} INFO - Failed to process /tmp/pymupdf_021a5339-744f-42b7-bd9b-9368b3efda7a.pdf.json: HTTPSConnectionPool(host='convertapi-index-unknown.svc.us-east1-aws.pinecone.io', port=443): Max retries exceeded with url: /vectors/upsert (Caused by NewConnectionError('<urllib3.connection.HTTPSConnection object at 0x7faefbad9650>: Failed to establish a new connection: [Errno -2] Name or service not known'))
[2024-10-07T06:19:36.912+0000] {connectionpool.py:813} WARNING - Retrying (Retry(total=2, connect=None, read=None, redirect=None, status=None)) after connection broken by 'NewConnectionError('<urllib3.connection.HTTPSConnection object at 0x7faefb9b0f90>: Failed to establish a new connection: [Errno -2] Name or service not known')': /vectors/upsert
[2024-10-07T06:19:36.921+0000] {connectionpool.py:813} WARNING - Retrying (Retry(total=1, connect=None, read=None, redirect=None, status=None)) after connection broken by 'NewConnectionError('<urllib3.connection.HTTPSConnection object at 0x7faefba89850>: Failed to establish a new connection: [Errno -2] Name or service not known')': /vectors/upsert
[2024-10-07T06:19:36.925+0000] {connectionpool.py:813} WARNING - Retrying (Retry(total=0, connect=None, read=None, redirect=None, status=None)) after connection broken by 'NewConnectionError('<urllib3.connection.HTTPSConnection object at 0x7faefba6a990>: Failed to establish a new connection: [Errno -2] Name or service not known')': /vectors/upsert
[2024-10-07T06:19:36.931+0000] {logging_mixin.py:137} INFO - Failed to process /tmp/pymupdf_366e2f2b-8632-4ef2-81eb-bc3877489217.pdf.json: HTTPSConnectionPool(host='convertapi-index-unknown.svc.us-east1-aws.pinecone.io', port=443): Max retries exceeded with url: /vectors/upsert (Caused by NewConnectionError('<urllib3.connection.HTTPSConnection object at 0x7faefbad34d0>: Failed to establish a new connection: [Errno -2] Name or service not known'))
[2024-10-07T06:19:37.203+0000] {connectionpool.py:813} WARNING - Retrying (Retry(total=2, connect=None, read=None, redirect=None, status=None)) after connection broken by 'NewConnectionError('<urllib3.connection.HTTPSConnection object at 0x7faefb9ab050>: Failed to establish a new connection: [Errno -2] Name or service not known')': /vectors/upsert
[2024-10-07T06:19:37.208+0000] {connectionpool.py:813} WARNING - Retrying (Retry(total=1, connect=None, read=None, redirect=None, status=None)) after connection broken by 'NewConnectionError('<urllib3.connection.HTTPSConnection object at 0x7faefba89e10>: Failed to establish a new connection: [Errno -2] Name or service not known')': /vectors/upsert
[2024-10-07T06:19:37.211+0000] {connectionpool.py:813} WARNING - Retrying (Retry(total=0, connect=None, read=None, redirect=None, status=None)) after connection broken by 'NewConnectionError('<urllib3.connection.HTTPSConnection object at 0x7faefba42510>: Failed to establish a new connection: [Errno -2] Name or service not known')': /vectors/upsert
[2024-10-07T06:19:37.216+0000] {logging_mixin.py:137} INFO - Failed to process /tmp/pymupdf_634fca59-03b2-4cdf-9ce4-0205df22f256.pdf.json: HTTPSConnectionPool(host='convertapi-index-unknown.svc.us-east1-aws.pinecone.io', port=443): Max retries exceeded with url: /vectors/upsert (Caused by NewConnectionError('<urllib3.connection.HTTPSConnection object at 0x7faefbad98d0>: Failed to establish a new connection: [Errno -2] Name or service not known'))
[2024-10-07T06:19:37.946+0000] {connectionpool.py:813} WARNING - Retrying (Retry(total=2, connect=None, read=None, redirect=None, status=None)) after connection broken by 'NewConnectionError('<urllib3.connection.HTTPSConnection object at 0x7faefba18a50>: Failed to establish a new connection: [Errno -2] Name or service not known')': /vectors/upsert
[2024-10-07T06:19:37.950+0000] {connectionpool.py:813} WARNING - Retrying (Retry(total=1, connect=None, read=None, redirect=None, status=None)) after connection broken by 'NewConnectionError('<urllib3.connection.HTTPSConnection object at 0x7faefbac1b10>: Failed to establish a new connection: [Errno -2] Name or service not known')': /vectors/upsert
[2024-10-07T06:19:37.954+0000] {connectionpool.py:813} WARNING - Retrying (Retry(total=0, connect=None, read=None, redirect=None, status=None)) after connection broken by 'NewConnectionError('<urllib3.connection.HTTPSConnection object at 0x7faefba30f90>: Failed to establish a new connection: [Errno -2] Name or service not known')': /vectors/upsert
[2024-10-07T06:19:37.960+0000] {logging_mixin.py:137} INFO - Failed to process /tmp/pymupdf_8f697523-6988-4c4f-8d72-760a45681f68.pdf.json: HTTPSConnectionPool(host='convertapi-index-unknown.svc.us-east1-aws.pinecone.io', port=443): Max retries exceeded with url: /vectors/upsert (Caused by NewConnectionError('<urllib3.connection.HTTPSConnection object at 0x7faefb9f3d10>: Failed to establish a new connection: [Errno -2] Name or service not known'))
[2024-10-07T06:19:38.428+0000] {connectionpool.py:813} WARNING - Retrying (Retry(total=2, connect=None, read=None, redirect=None, status=None)) after connection broken by 'NewConnectionError('<urllib3.connection.HTTPSConnection object at 0x7faefba05cd0>: Failed to establish a new connection: [Errno -2] Name or service not known')': /vectors/upsert
[2024-10-07T06:19:38.433+0000] {connectionpool.py:813} WARNING - Retrying (Retry(total=1, connect=None, read=None, redirect=None, status=None)) after connection broken by 'NewConnectionError('<urllib3.connection.HTTPSConnection object at 0x7faefba05490>: Failed to establish a new connection: [Errno -2] Name or service not known')': /vectors/upsert
[2024-10-07T06:19:38.438+0000] {connectionpool.py:813} WARNING - Retrying (Retry(total=0, connect=None, read=None, redirect=None, status=None)) after connection broken by 'NewConnectionError('<urllib3.connection.HTTPSConnection object at 0x7faefba42cd0>: Failed to establish a new connection: [Errno -2] Name or service not known')': /vectors/upsert
[2024-10-07T06:19:38.443+0000] {logging_mixin.py:137} INFO - Failed to process /tmp/pymupdf_example.pdf.json: HTTPSConnectionPool(host='convertapi-index-unknown.svc.us-east1-aws.pinecone.io', port=443): Max retries exceeded with url: /vectors/upsert (Caused by NewConnectionError('<urllib3.connection.HTTPSConnection object at 0x7faefbaa21d0>: Failed to establish a new connection: [Errno -2] Name or service not known'))
[2024-10-07T06:19:38.443+0000] {python.py:177} INFO - Done. Returned value was: None
[2024-10-07T06:19:38.478+0000] {taskinstance.py:1327} INFO - Marking task as SUCCESS. dag_id=pinecone_embedding_test_dag, task_id=embed_convertapi_pages, execution_date=20241007T061922, start_date=20241007T061935, end_date=20241007T061938
[2024-10-07T06:19:38.527+0000] {local_task_job.py:159} INFO - Task exited with return code 0
[2024-10-07T06:19:38.581+0000] {taskinstance.py:2582} INFO - 0 downstream tasks scheduled from follow-on schedule check
